2025-10-29 14:13:13,622 [INFO] Bot starting. Allowed IDs: {12345678}
2025-10-29 14:13:52,067 [INFO] Unauthorized access attempt by user_id=8151381533
{"type": "unauthorized_attempt", "user_id": 8151381533, "username": null, "local_ts": "2025-10-29T08:43:53.611117Z"}
2025-10-29 14:14:26,155 [INFO] Interrupted by user. Exiting.
2025-10-29 14:14:45,754 [INFO] Bot starting. Allowed IDs: {8151381533}
2025-10-29 14:16:33,248 [ERROR] Error in polling loop: ('Connection aborted.', ConnectionResetError(104, 'Connection reset by peer'))
Traceback (most recent call last):
  File "/home/astra/Desktop/telebot/myenv/lib/python3.13/site-packages/urllib3/connectionpool.py", line 787, in urlopen
    response = self._make_request(
        conn,
    ...<10 lines>...
        **response_kw,
    )
  File "/home/astra/Desktop/telebot/myenv/lib/python3.13/site-packages/urllib3/connectionpool.py", line 488, in _make_request
    raise new_e
  File "/home/astra/Desktop/telebot/myenv/lib/python3.13/site-packages/urllib3/connectionpool.py", line 464, in _make_request
    self._validate_conn(conn)
    ~~~~~~~~~~~~~~~~~~~^^^^^^
  File "/home/astra/Desktop/telebot/myenv/lib/python3.13/site-packages/urllib3/connectionpool.py", line 1093, in _validate_conn
    conn.connect()
    ~~~~~~~~~~~~^^
  File "/home/astra/Desktop/telebot/myenv/lib/python3.13/site-packages/urllib3/connection.py", line 790, in connect
    sock_and_verified = _ssl_wrap_socket_and_match_hostname(
        sock=sock,
    ...<14 lines>...
        assert_fingerprint=self.assert_fingerprint,
    )
  File "/home/astra/Desktop/telebot/myenv/lib/python3.13/site-packages/urllib3/connection.py", line 969, in _ssl_wrap_socket_and_match_hostname
    ssl_sock = ssl_wrap_socket(
        sock=sock,
    ...<8 lines>...
        tls_in_tls=tls_in_tls,
    )
  File "/home/astra/Desktop/telebot/myenv/lib/python3.13/site-packages/urllib3/util/ssl_.py", line 480, in ssl_wrap_socket
    ssl_sock = _ssl_wrap_socket_impl(sock, context, tls_in_tls, server_hostname)
  File "/home/astra/Desktop/telebot/myenv/lib/python3.13/site-packages/urllib3/util/ssl_.py", line 524, in _ssl_wrap_socket_impl
    return ssl_context.wrap_socket(sock, server_hostname=server_hostname)
           ~~~~~~~~~~~~~~~~~~~~~~~^^^^^^^^^^^^^^^^^^^^^^^^^^^^^^^^^^^^^^^
  File "/usr/lib/python3.13/ssl.py", line 455, in wrap_socket
    return self.sslsocket_class._create(
           ~~~~~~~~~~~~~~~~~~~~~~~~~~~~^
        sock=sock,
        ^^^^^^^^^^
    ...<5 lines>...
        session=session
        ^^^^^^^^^^^^^^^
    )
    ^
  File "/usr/lib/python3.13/ssl.py", line 1076, in _create
    self.do_handshake()
    ~~~~~~~~~~~~~~~~~^^
  File "/usr/lib/python3.13/ssl.py", line 1372, in do_handshake
    self._sslobj.do_handshake()
    ~~~~~~~~~~~~~~~~~~~~~~~~~^^
ConnectionResetError: [Errno 104] Connection reset by peer

During handling of the above exception, another exception occurred:

Traceback (most recent call last):
  File "/home/astra/Desktop/telebot/myenv/lib/python3.13/site-packages/requests/adapters.py", line 644, in send
    resp = conn.urlopen(
        method=request.method,
    ...<9 lines>...
        chunked=chunked,
    )
  File "/home/astra/Desktop/telebot/myenv/lib/python3.13/site-packages/urllib3/connectionpool.py", line 841, in urlopen
    retries = retries.increment(
        method, url, error=new_e, _pool=self, _stacktrace=sys.exc_info()[2]
    )
  File "/home/astra/Desktop/telebot/myenv/lib/python3.13/site-packages/urllib3/util/retry.py", line 474, in increment
    raise reraise(type(error), error, _stacktrace)
          ~~~~~~~^^^^^^^^^^^^^^^^^^^^^^^^^^^^^^^^^
  File "/home/astra/Desktop/telebot/myenv/lib/python3.13/site-packages/urllib3/util/util.py", line 38, in reraise
    raise value.with_traceback(tb)
  File "/home/astra/Desktop/telebot/myenv/lib/python3.13/site-packages/urllib3/connectionpool.py", line 787, in urlopen
    response = self._make_request(
        conn,
    ...<10 lines>...
        **response_kw,
    )
  File "/home/astra/Desktop/telebot/myenv/lib/python3.13/site-packages/urllib3/connectionpool.py", line 488, in _make_request
    raise new_e
  File "/home/astra/Desktop/telebot/myenv/lib/python3.13/site-packages/urllib3/connectionpool.py", line 464, in _make_request
    self._validate_conn(conn)
    ~~~~~~~~~~~~~~~~~~~^^^^^^
  File "/home/astra/Desktop/telebot/myenv/lib/python3.13/site-packages/urllib3/connectionpool.py", line 1093, in _validate_conn
    conn.connect()
    ~~~~~~~~~~~~^^
  File "/home/astra/Desktop/telebot/myenv/lib/python3.13/site-packages/urllib3/connection.py", line 790, in connect
    sock_and_verified = _ssl_wrap_socket_and_match_hostname(
        sock=sock,
    ...<14 lines>...
        assert_fingerprint=self.assert_fingerprint,
    )
  File "/home/astra/Desktop/telebot/myenv/lib/python3.13/site-packages/urllib3/connection.py", line 969, in _ssl_wrap_socket_and_match_hostname
    ssl_sock = ssl_wrap_socket(
        sock=sock,
    ...<8 lines>...
        tls_in_tls=tls_in_tls,
    )
  File "/home/astra/Desktop/telebot/myenv/lib/python3.13/site-packages/urllib3/util/ssl_.py", line 480, in ssl_wrap_socket
    ssl_sock = _ssl_wrap_socket_impl(sock, context, tls_in_tls, server_hostname)
  File "/home/astra/Desktop/telebot/myenv/lib/python3.13/site-packages/urllib3/util/ssl_.py", line 524, in _ssl_wrap_socket_impl
    return ssl_context.wrap_socket(sock, server_hostname=server_hostname)
           ~~~~~~~~~~~~~~~~~~~~~~~^^^^^^^^^^^^^^^^^^^^^^^^^^^^^^^^^^^^^^^
  File "/usr/lib/python3.13/ssl.py", line 455, in wrap_socket
    return self.sslsocket_class._create(
           ~~~~~~~~~~~~~~~~~~~~~~~~~~~~^
        sock=sock,
        ^^^^^^^^^^
    ...<5 lines>...
        session=session
        ^^^^^^^^^^^^^^^
    )
    ^
  File "/usr/lib/python3.13/ssl.py", line 1076, in _create
    self.do_handshake()
    ~~~~~~~~~~~~~~~~~^^
  File "/usr/lib/python3.13/ssl.py", line 1372, in do_handshake
    self._sslobj.do_handshake()
    ~~~~~~~~~~~~~~~~~~~~~~~~~^^
urllib3.exceptions.ProtocolError: ('Connection aborted.', ConnectionResetError(104, 'Connection reset by peer'))

During handling of the above exception, another exception occurred:

Traceback (most recent call last):
  File "/home/astra/Desktop/telebot/telegrambot.py", line 483, in main_poll_loop
    updates = get_updates(offset=offset, timeout=int(POLL_INTERVAL))
  File "/home/astra/Desktop/telebot/telegrambot.py", line 439, in get_updates
    r = requests.get(f"{API_BASE}/getUpdates", params=params, timeout=timeout+10)
  File "/home/astra/Desktop/telebot/myenv/lib/python3.13/site-packages/requests/api.py", line 73, in get
    return request("get", url, params=params, **kwargs)
  File "/home/astra/Desktop/telebot/myenv/lib/python3.13/site-packages/requests/api.py", line 59, in request
    return session.request(method=method, url=url, **kwargs)
           ~~~~~~~~~~~~~~~^^^^^^^^^^^^^^^^^^^^^^^^^^^^^^^^^^
  File "/home/astra/Desktop/telebot/myenv/lib/python3.13/site-packages/requests/sessions.py", line 589, in request
    resp = self.send(prep, **send_kwargs)
  File "/home/astra/Desktop/telebot/myenv/lib/python3.13/site-packages/requests/sessions.py", line 703, in send
    r = adapter.send(request, **kwargs)
  File "/home/astra/Desktop/telebot/myenv/lib/python3.13/site-packages/requests/adapters.py", line 659, in send
    raise ConnectionError(err, request=request)
requests.exceptions.ConnectionError: ('Connection aborted.', ConnectionResetError(104, 'Connection reset by peer'))
2025-10-29 14:16:58,569 [ERROR] Error in polling loop: ('Connection aborted.', ConnectionResetError(104, 'Connection reset by peer'))
Traceback (most recent call last):
  File "/home/astra/Desktop/telebot/myenv/lib/python3.13/site-packages/urllib3/connectionpool.py", line 787, in urlopen
    response = self._make_request(
        conn,
    ...<10 lines>...
        **response_kw,
    )
  File "/home/astra/Desktop/telebot/myenv/lib/python3.13/site-packages/urllib3/connectionpool.py", line 488, in _make_request
    raise new_e
  File "/home/astra/Desktop/telebot/myenv/lib/python3.13/site-packages/urllib3/connectionpool.py", line 464, in _make_request
    self._validate_conn(conn)
    ~~~~~~~~~~~~~~~~~~~^^^^^^
  File "/home/astra/Desktop/telebot/myenv/lib/python3.13/site-packages/urllib3/connectionpool.py", line 1093, in _validate_conn
    conn.connect()
    ~~~~~~~~~~~~^^
  File "/home/astra/Desktop/telebot/myenv/lib/python3.13/site-packages/urllib3/connection.py", line 790, in connect
    sock_and_verified = _ssl_wrap_socket_and_match_hostname(
        sock=sock,
    ...<14 lines>...
        assert_fingerprint=self.assert_fingerprint,
    )
  File "/home/astra/Desktop/telebot/myenv/lib/python3.13/site-packages/urllib3/connection.py", line 969, in _ssl_wrap_socket_and_match_hostname
    ssl_sock = ssl_wrap_socket(
        sock=sock,
    ...<8 lines>...
        tls_in_tls=tls_in_tls,
    )
  File "/home/astra/Desktop/telebot/myenv/lib/python3.13/site-packages/urllib3/util/ssl_.py", line 480, in ssl_wrap_socket
    ssl_sock = _ssl_wrap_socket_impl(sock, context, tls_in_tls, server_hostname)
  File "/home/astra/Desktop/telebot/myenv/lib/python3.13/site-packages/urllib3/util/ssl_.py", line 524, in _ssl_wrap_socket_impl
    return ssl_context.wrap_socket(sock, server_hostname=server_hostname)
           ~~~~~~~~~~~~~~~~~~~~~~~^^^^^^^^^^^^^^^^^^^^^^^^^^^^^^^^^^^^^^^
  File "/usr/lib/python3.13/ssl.py", line 455, in wrap_socket
    return self.sslsocket_class._create(
           ~~~~~~~~~~~~~~~~~~~~~~~~~~~~^
        sock=sock,
        ^^^^^^^^^^
    ...<5 lines>...
        session=session
        ^^^^^^^^^^^^^^^
    )
    ^
  File "/usr/lib/python3.13/ssl.py", line 1076, in _create
    self.do_handshake()
    ~~~~~~~~~~~~~~~~~^^
  File "/usr/lib/python3.13/ssl.py", line 1372, in do_handshake
    self._sslobj.do_handshake()
    ~~~~~~~~~~~~~~~~~~~~~~~~~^^
ConnectionResetError: [Errno 104] Connection reset by peer

During handling of the above exception, another exception occurred:

Traceback (most recent call last):
  File "/home/astra/Desktop/telebot/myenv/lib/python3.13/site-packages/requests/adapters.py", line 644, in send
    resp = conn.urlopen(
        method=request.method,
    ...<9 lines>...
        chunked=chunked,
    )
  File "/home/astra/Desktop/telebot/myenv/lib/python3.13/site-packages/urllib3/connectionpool.py", line 841, in urlopen
    retries = retries.increment(
        method, url, error=new_e, _pool=self, _stacktrace=sys.exc_info()[2]
    )
  File "/home/astra/Desktop/telebot/myenv/lib/python3.13/site-packages/urllib3/util/retry.py", line 474, in increment
    raise reraise(type(error), error, _stacktrace)
          ~~~~~~~^^^^^^^^^^^^^^^^^^^^^^^^^^^^^^^^^
  File "/home/astra/Desktop/telebot/myenv/lib/python3.13/site-packages/urllib3/util/util.py", line 38, in reraise
    raise value.with_traceback(tb)
  File "/home/astra/Desktop/telebot/myenv/lib/python3.13/site-packages/urllib3/connectionpool.py", line 787, in urlopen
    response = self._make_request(
        conn,
    ...<10 lines>...
        **response_kw,
    )
  File "/home/astra/Desktop/telebot/myenv/lib/python3.13/site-packages/urllib3/connectionpool.py", line 488, in _make_request
    raise new_e
  File "/home/astra/Desktop/telebot/myenv/lib/python3.13/site-packages/urllib3/connectionpool.py", line 464, in _make_request
    self._validate_conn(conn)
    ~~~~~~~~~~~~~~~~~~~^^^^^^
  File "/home/astra/Desktop/telebot/myenv/lib/python3.13/site-packages/urllib3/connectionpool.py", line 1093, in _validate_conn
    conn.connect()
    ~~~~~~~~~~~~^^
  File "/home/astra/Desktop/telebot/myenv/lib/python3.13/site-packages/urllib3/connection.py", line 790, in connect
    sock_and_verified = _ssl_wrap_socket_and_match_hostname(
        sock=sock,
    ...<14 lines>...
        assert_fingerprint=self.assert_fingerprint,
    )
  File "/home/astra/Desktop/telebot/myenv/lib/python3.13/site-packages/urllib3/connection.py", line 969, in _ssl_wrap_socket_and_match_hostname
    ssl_sock = ssl_wrap_socket(
        sock=sock,
    ...<8 lines>...
        tls_in_tls=tls_in_tls,
    )
  File "/home/astra/Desktop/telebot/myenv/lib/python3.13/site-packages/urllib3/util/ssl_.py", line 480, in ssl_wrap_socket
    ssl_sock = _ssl_wrap_socket_impl(sock, context, tls_in_tls, server_hostname)
  File "/home/astra/Desktop/telebot/myenv/lib/python3.13/site-packages/urllib3/util/ssl_.py", line 524, in _ssl_wrap_socket_impl
    return ssl_context.wrap_socket(sock, server_hostname=server_hostname)
           ~~~~~~~~~~~~~~~~~~~~~~~^^^^^^^^^^^^^^^^^^^^^^^^^^^^^^^^^^^^^^^
  File "/usr/lib/python3.13/ssl.py", line 455, in wrap_socket
    return self.sslsocket_class._create(
           ~~~~~~~~~~~~~~~~~~~~~~~~~~~~^
        sock=sock,
        ^^^^^^^^^^
    ...<5 lines>...
        session=session
        ^^^^^^^^^^^^^^^
    )
    ^
  File "/usr/lib/python3.13/ssl.py", line 1076, in _create
    self.do_handshake()
    ~~~~~~~~~~~~~~~~~^^
  File "/usr/lib/python3.13/ssl.py", line 1372, in do_handshake
    self._sslobj.do_handshake()
    ~~~~~~~~~~~~~~~~~~~~~~~~~^^
urllib3.exceptions.ProtocolError: ('Connection aborted.', ConnectionResetError(104, 'Connection reset by peer'))

During handling of the above exception, another exception occurred:

Traceback (most recent call last):
  File "/home/astra/Desktop/telebot/telegrambot.py", line 483, in main_poll_loop
    updates = get_updates(offset=offset, timeout=int(POLL_INTERVAL))
  File "/home/astra/Desktop/telebot/telegrambot.py", line 439, in get_updates
    r = requests.get(f"{API_BASE}/getUpdates", params=params, timeout=timeout+10)
  File "/home/astra/Desktop/telebot/myenv/lib/python3.13/site-packages/requests/api.py", line 73, in get
    return request("get", url, params=params, **kwargs)
  File "/home/astra/Desktop/telebot/myenv/lib/python3.13/site-packages/requests/api.py", line 59, in request
    return session.request(method=method, url=url, **kwargs)
           ~~~~~~~~~~~~~~~^^^^^^^^^^^^^^^^^^^^^^^^^^^^^^^^^^
  File "/home/astra/Desktop/telebot/myenv/lib/python3.13/site-packages/requests/sessions.py", line 589, in request
    resp = self.send(prep, **send_kwargs)
  File "/home/astra/Desktop/telebot/myenv/lib/python3.13/site-packages/requests/sessions.py", line 703, in send
    r = adapter.send(request, **kwargs)
  File "/home/astra/Desktop/telebot/myenv/lib/python3.13/site-packages/requests/adapters.py", line 659, in send
    raise ConnectionError(err, request=request)
requests.exceptions.ConnectionError: ('Connection aborted.', ConnectionResetError(104, 'Connection reset by peer'))
2025-10-29 14:18:33,604 [ERROR] Error in polling loop: ('Connection aborted.', ConnectionResetError(104, 'Connection reset by peer'))
Traceback (most recent call last):
  File "/home/astra/Desktop/telebot/myenv/lib/python3.13/site-packages/urllib3/connectionpool.py", line 787, in urlopen
    response = self._make_request(
        conn,
    ...<10 lines>...
        **response_kw,
    )
  File "/home/astra/Desktop/telebot/myenv/lib/python3.13/site-packages/urllib3/connectionpool.py", line 488, in _make_request
    raise new_e
  File "/home/astra/Desktop/telebot/myenv/lib/python3.13/site-packages/urllib3/connectionpool.py", line 464, in _make_request
    self._validate_conn(conn)
    ~~~~~~~~~~~~~~~~~~~^^^^^^
  File "/home/astra/Desktop/telebot/myenv/lib/python3.13/site-packages/urllib3/connectionpool.py", line 1093, in _validate_conn
    conn.connect()
    ~~~~~~~~~~~~^^
  File "/home/astra/Desktop/telebot/myenv/lib/python3.13/site-packages/urllib3/connection.py", line 790, in connect
    sock_and_verified = _ssl_wrap_socket_and_match_hostname(
        sock=sock,
    ...<14 lines>...
        assert_fingerprint=self.assert_fingerprint,
    )
  File "/home/astra/Desktop/telebot/myenv/lib/python3.13/site-packages/urllib3/connection.py", line 969, in _ssl_wrap_socket_and_match_hostname
    ssl_sock = ssl_wrap_socket(
        sock=sock,
    ...<8 lines>...
        tls_in_tls=tls_in_tls,
    )
  File "/home/astra/Desktop/telebot/myenv/lib/python3.13/site-packages/urllib3/util/ssl_.py", line 480, in ssl_wrap_socket
    ssl_sock = _ssl_wrap_socket_impl(sock, context, tls_in_tls, server_hostname)
  File "/home/astra/Desktop/telebot/myenv/lib/python3.13/site-packages/urllib3/util/ssl_.py", line 524, in _ssl_wrap_socket_impl
    return ssl_context.wrap_socket(sock, server_hostname=server_hostname)
           ~~~~~~~~~~~~~~~~~~~~~~~^^^^^^^^^^^^^^^^^^^^^^^^^^^^^^^^^^^^^^^
  File "/usr/lib/python3.13/ssl.py", line 455, in wrap_socket
    return self.sslsocket_class._create(
           ~~~~~~~~~~~~~~~~~~~~~~~~~~~~^
        sock=sock,
        ^^^^^^^^^^
    ...<5 lines>...
        session=session
        ^^^^^^^^^^^^^^^
    )
    ^
  File "/usr/lib/python3.13/ssl.py", line 1076, in _create
    self.do_handshake()
    ~~~~~~~~~~~~~~~~~^^
  File "/usr/lib/python3.13/ssl.py", line 1372, in do_handshake
    self._sslobj.do_handshake()
    ~~~~~~~~~~~~~~~~~~~~~~~~~^^
ConnectionResetError: [Errno 104] Connection reset by peer

During handling of the above exception, another exception occurred:

Traceback (most recent call last):
  File "/home/astra/Desktop/telebot/myenv/lib/python3.13/site-packages/requests/adapters.py", line 644, in send
    resp = conn.urlopen(
        method=request.method,
    ...<9 lines>...
        chunked=chunked,
    )
  File "/home/astra/Desktop/telebot/myenv/lib/python3.13/site-packages/urllib3/connectionpool.py", line 841, in urlopen
    retries = retries.increment(
        method, url, error=new_e, _pool=self, _stacktrace=sys.exc_info()[2]
    )
  File "/home/astra/Desktop/telebot/myenv/lib/python3.13/site-packages/urllib3/util/retry.py", line 474, in increment
    raise reraise(type(error), error, _stacktrace)
          ~~~~~~~^^^^^^^^^^^^^^^^^^^^^^^^^^^^^^^^^
  File "/home/astra/Desktop/telebot/myenv/lib/python3.13/site-packages/urllib3/util/util.py", line 38, in reraise
    raise value.with_traceback(tb)
  File "/home/astra/Desktop/telebot/myenv/lib/python3.13/site-packages/urllib3/connectionpool.py", line 787, in urlopen
    response = self._make_request(
        conn,
    ...<10 lines>...
        **response_kw,
    )
  File "/home/astra/Desktop/telebot/myenv/lib/python3.13/site-packages/urllib3/connectionpool.py", line 488, in _make_request
    raise new_e
  File "/home/astra/Desktop/telebot/myenv/lib/python3.13/site-packages/urllib3/connectionpool.py", line 464, in _make_request
    self._validate_conn(conn)
    ~~~~~~~~~~~~~~~~~~~^^^^^^
  File "/home/astra/Desktop/telebot/myenv/lib/python3.13/site-packages/urllib3/connectionpool.py", line 1093, in _validate_conn
    conn.connect()
    ~~~~~~~~~~~~^^
  File "/home/astra/Desktop/telebot/myenv/lib/python3.13/site-packages/urllib3/connection.py", line 790, in connect
    sock_and_verified = _ssl_wrap_socket_and_match_hostname(
        sock=sock,
    ...<14 lines>...
        assert_fingerprint=self.assert_fingerprint,
    )
  File "/home/astra/Desktop/telebot/myenv/lib/python3.13/site-packages/urllib3/connection.py", line 969, in _ssl_wrap_socket_and_match_hostname
    ssl_sock = ssl_wrap_socket(
        sock=sock,
    ...<8 lines>...
        tls_in_tls=tls_in_tls,
    )
  File "/home/astra/Desktop/telebot/myenv/lib/python3.13/site-packages/urllib3/util/ssl_.py", line 480, in ssl_wrap_socket
    ssl_sock = _ssl_wrap_socket_impl(sock, context, tls_in_tls, server_hostname)
  File "/home/astra/Desktop/telebot/myenv/lib/python3.13/site-packages/urllib3/util/ssl_.py", line 524, in _ssl_wrap_socket_impl
    return ssl_context.wrap_socket(sock, server_hostname=server_hostname)
           ~~~~~~~~~~~~~~~~~~~~~~~^^^^^^^^^^^^^^^^^^^^^^^^^^^^^^^^^^^^^^^
  File "/usr/lib/python3.13/ssl.py", line 455, in wrap_socket
    return self.sslsocket_class._create(
           ~~~~~~~~~~~~~~~~~~~~~~~~~~~~^
        sock=sock,
        ^^^^^^^^^^
    ...<5 lines>...
        session=session
        ^^^^^^^^^^^^^^^
    )
    ^
  File "/usr/lib/python3.13/ssl.py", line 1076, in _create
    self.do_handshake()
    ~~~~~~~~~~~~~~~~~^^
  File "/usr/lib/python3.13/ssl.py", line 1372, in do_handshake
    self._sslobj.do_handshake()
    ~~~~~~~~~~~~~~~~~~~~~~~~~^^
urllib3.exceptions.ProtocolError: ('Connection aborted.', ConnectionResetError(104, 'Connection reset by peer'))

During handling of the above exception, another exception occurred:

Traceback (most recent call last):
  File "/home/astra/Desktop/telebot/telegrambot.py", line 483, in main_poll_loop
    updates = get_updates(offset=offset, timeout=int(POLL_INTERVAL))
  File "/home/astra/Desktop/telebot/telegrambot.py", line 439, in get_updates
    r = requests.get(f"{API_BASE}/getUpdates", params=params, timeout=timeout+10)
  File "/home/astra/Desktop/telebot/myenv/lib/python3.13/site-packages/requests/api.py", line 73, in get
    return request("get", url, params=params, **kwargs)
  File "/home/astra/Desktop/telebot/myenv/lib/python3.13/site-packages/requests/api.py", line 59, in request
    return session.request(method=method, url=url, **kwargs)
           ~~~~~~~~~~~~~~~^^^^^^^^^^^^^^^^^^^^^^^^^^^^^^^^^^
  File "/home/astra/Desktop/telebot/myenv/lib/python3.13/site-packages/requests/sessions.py", line 589, in request
    resp = self.send(prep, **send_kwargs)
  File "/home/astra/Desktop/telebot/myenv/lib/python3.13/site-packages/requests/sessions.py", line 703, in send
    r = adapter.send(request, **kwargs)
  File "/home/astra/Desktop/telebot/myenv/lib/python3.13/site-packages/requests/adapters.py", line 659, in send
    raise ConnectionError(err, request=request)
requests.exceptions.ConnectionError: ('Connection aborted.', ConnectionResetError(104, 'Connection reset by peer'))
2025-10-29 14:19:10,404 [ERROR] Failed to save output files: 'FreeTypeFont' object has no attribute 'getsize'
Traceback (most recent call last):
  File "/home/astra/Desktop/telebot/telegrambot.py", line 394, in handle_scan
    render_text_to_image(combined, img_path)
    ~~~~~~~~~~~~~~~~~~~~^^^^^^^^^^^^^^^^^^^^
  File "/home/astra/Desktop/telebot/telegrambot.py", line 254, in render_text_to_image
    char_width, char_height = font.getsize("M")
                              ^^^^^^^^^^^^
AttributeError: 'FreeTypeFont' object has no attribute 'getsize'
{"type": "error", "meta": {"requester_username": "Pugazh", "requester_id": 8151381533, "target": "avccollege.net", "nmap_args": ["-sV"], "timestamp": "2025-10-29 08:48:43Z", "comment": null}, "error": "'FreeTypeFont' object has no attribute 'getsize'", "local_ts": "2025-10-29T08:49:11.580709Z"}
2025-10-29 14:21:31,274 [ERROR] Error in polling loop: ('Connection aborted.', ConnectionResetError(104, 'Connection reset by peer'))
Traceback (most recent call last):
  File "/home/astra/Desktop/telebot/myenv/lib/python3.13/site-packages/urllib3/connectionpool.py", line 787, in urlopen
    response = self._make_request(
        conn,
    ...<10 lines>...
        **response_kw,
    )
  File "/home/astra/Desktop/telebot/myenv/lib/python3.13/site-packages/urllib3/connectionpool.py", line 488, in _make_request
    raise new_e
  File "/home/astra/Desktop/telebot/myenv/lib/python3.13/site-packages/urllib3/connectionpool.py", line 464, in _make_request
    self._validate_conn(conn)
    ~~~~~~~~~~~~~~~~~~~^^^^^^
  File "/home/astra/Desktop/telebot/myenv/lib/python3.13/site-packages/urllib3/connectionpool.py", line 1093, in _validate_conn
    conn.connect()
    ~~~~~~~~~~~~^^
  File "/home/astra/Desktop/telebot/myenv/lib/python3.13/site-packages/urllib3/connection.py", line 790, in connect
    sock_and_verified = _ssl_wrap_socket_and_match_hostname(
        sock=sock,
    ...<14 lines>...
        assert_fingerprint=self.assert_fingerprint,
    )
  File "/home/astra/Desktop/telebot/myenv/lib/python3.13/site-packages/urllib3/connection.py", line 969, in _ssl_wrap_socket_and_match_hostname
    ssl_sock = ssl_wrap_socket(
        sock=sock,
    ...<8 lines>...
        tls_in_tls=tls_in_tls,
    )
  File "/home/astra/Desktop/telebot/myenv/lib/python3.13/site-packages/urllib3/util/ssl_.py", line 480, in ssl_wrap_socket
    ssl_sock = _ssl_wrap_socket_impl(sock, context, tls_in_tls, server_hostname)
  File "/home/astra/Desktop/telebot/myenv/lib/python3.13/site-packages/urllib3/util/ssl_.py", line 524, in _ssl_wrap_socket_impl
    return ssl_context.wrap_socket(sock, server_hostname=server_hostname)
           ~~~~~~~~~~~~~~~~~~~~~~~^^^^^^^^^^^^^^^^^^^^^^^^^^^^^^^^^^^^^^^
  File "/usr/lib/python3.13/ssl.py", line 455, in wrap_socket
    return self.sslsocket_class._create(
           ~~~~~~~~~~~~~~~~~~~~~~~~~~~~^
        sock=sock,
        ^^^^^^^^^^
    ...<5 lines>...
        session=session
        ^^^^^^^^^^^^^^^
    )
    ^
  File "/usr/lib/python3.13/ssl.py", line 1076, in _create
    self.do_handshake()
    ~~~~~~~~~~~~~~~~~^^
  File "/usr/lib/python3.13/ssl.py", line 1372, in do_handshake
    self._sslobj.do_handshake()
    ~~~~~~~~~~~~~~~~~~~~~~~~~^^
ConnectionResetError: [Errno 104] Connection reset by peer

During handling of the above exception, another exception occurred:

Traceback (most recent call last):
  File "/home/astra/Desktop/telebot/myenv/lib/python3.13/site-packages/requests/adapters.py", line 644, in send
    resp = conn.urlopen(
        method=request.method,
    ...<9 lines>...
        chunked=chunked,
    )
  File "/home/astra/Desktop/telebot/myenv/lib/python3.13/site-packages/urllib3/connectionpool.py", line 841, in urlopen
    retries = retries.increment(
        method, url, error=new_e, _pool=self, _stacktrace=sys.exc_info()[2]
    )
  File "/home/astra/Desktop/telebot/myenv/lib/python3.13/site-packages/urllib3/util/retry.py", line 474, in increment
    raise reraise(type(error), error, _stacktrace)
          ~~~~~~~^^^^^^^^^^^^^^^^^^^^^^^^^^^^^^^^^
  File "/home/astra/Desktop/telebot/myenv/lib/python3.13/site-packages/urllib3/util/util.py", line 38, in reraise
    raise value.with_traceback(tb)
  File "/home/astra/Desktop/telebot/myenv/lib/python3.13/site-packages/urllib3/connectionpool.py", line 787, in urlopen
    response = self._make_request(
        conn,
    ...<10 lines>...
        **response_kw,
    )
  File "/home/astra/Desktop/telebot/myenv/lib/python3.13/site-packages/urllib3/connectionpool.py", line 488, in _make_request
    raise new_e
  File "/home/astra/Desktop/telebot/myenv/lib/python3.13/site-packages/urllib3/connectionpool.py", line 464, in _make_request
    self._validate_conn(conn)
    ~~~~~~~~~~~~~~~~~~~^^^^^^
  File "/home/astra/Desktop/telebot/myenv/lib/python3.13/site-packages/urllib3/connectionpool.py", line 1093, in _validate_conn
    conn.connect()
    ~~~~~~~~~~~~^^
  File "/home/astra/Desktop/telebot/myenv/lib/python3.13/site-packages/urllib3/connection.py", line 790, in connect
    sock_and_verified = _ssl_wrap_socket_and_match_hostname(
        sock=sock,
    ...<14 lines>...
        assert_fingerprint=self.assert_fingerprint,
    )
  File "/home/astra/Desktop/telebot/myenv/lib/python3.13/site-packages/urllib3/connection.py", line 969, in _ssl_wrap_socket_and_match_hostname
    ssl_sock = ssl_wrap_socket(
        sock=sock,
    ...<8 lines>...
        tls_in_tls=tls_in_tls,
    )
  File "/home/astra/Desktop/telebot/myenv/lib/python3.13/site-packages/urllib3/util/ssl_.py", line 480, in ssl_wrap_socket
    ssl_sock = _ssl_wrap_socket_impl(sock, context, tls_in_tls, server_hostname)
  File "/home/astra/Desktop/telebot/myenv/lib/python3.13/site-packages/urllib3/util/ssl_.py", line 524, in _ssl_wrap_socket_impl
    return ssl_context.wrap_socket(sock, server_hostname=server_hostname)
           ~~~~~~~~~~~~~~~~~~~~~~~^^^^^^^^^^^^^^^^^^^^^^^^^^^^^^^^^^^^^^^
  File "/usr/lib/python3.13/ssl.py", line 455, in wrap_socket
    return self.sslsocket_class._create(
           ~~~~~~~~~~~~~~~~~~~~~~~~~~~~^
        sock=sock,
        ^^^^^^^^^^
    ...<5 lines>...
        session=session
        ^^^^^^^^^^^^^^^
    )
    ^
  File "/usr/lib/python3.13/ssl.py", line 1076, in _create
    self.do_handshake()
    ~~~~~~~~~~~~~~~~~^^
  File "/usr/lib/python3.13/ssl.py", line 1372, in do_handshake
    self._sslobj.do_handshake()
    ~~~~~~~~~~~~~~~~~~~~~~~~~^^
urllib3.exceptions.ProtocolError: ('Connection aborted.', ConnectionResetError(104, 'Connection reset by peer'))

During handling of the above exception, another exception occurred:

Traceback (most recent call last):
  File "/home/astra/Desktop/telebot/telegrambot.py", line 483, in main_poll_loop
    updates = get_updates(offset=offset, timeout=int(POLL_INTERVAL))
  File "/home/astra/Desktop/telebot/telegrambot.py", line 439, in get_updates
    r = requests.get(f"{API_BASE}/getUpdates", params=params, timeout=timeout+10)
  File "/home/astra/Desktop/telebot/myenv/lib/python3.13/site-packages/requests/api.py", line 73, in get
    return request("get", url, params=params, **kwargs)
  File "/home/astra/Desktop/telebot/myenv/lib/python3.13/site-packages/requests/api.py", line 59, in request
    return session.request(method=method, url=url, **kwargs)
           ~~~~~~~~~~~~~~~^^^^^^^^^^^^^^^^^^^^^^^^^^^^^^^^^^
  File "/home/astra/Desktop/telebot/myenv/lib/python3.13/site-packages/requests/sessions.py", line 589, in request
    resp = self.send(prep, **send_kwargs)
  File "/home/astra/Desktop/telebot/myenv/lib/python3.13/site-packages/requests/sessions.py", line 703, in send
    r = adapter.send(request, **kwargs)
  File "/home/astra/Desktop/telebot/myenv/lib/python3.13/site-packages/requests/adapters.py", line 659, in send
    raise ConnectionError(err, request=request)
requests.exceptions.ConnectionError: ('Connection aborted.', ConnectionResetError(104, 'Connection reset by peer'))
